[2024-09-17 12:36:21,671] {taskinstance.py:1160} INFO - Dependencies all met for <TaskInstance: scrapy_spiders_dag.run_hespress_task scheduled__2024-09-17T11:36:18.915604+00:00 [queued]>
[2024-09-17 12:36:21,697] {taskinstance.py:1160} INFO - Dependencies all met for <TaskInstance: scrapy_spiders_dag.run_hespress_task scheduled__2024-09-17T11:36:18.915604+00:00 [queued]>
[2024-09-17 12:36:21,697] {taskinstance.py:1357} INFO - 
--------------------------------------------------------------------------------
[2024-09-17 12:36:21,698] {taskinstance.py:1358} INFO - Starting attempt 1 of 1
[2024-09-17 12:36:21,698] {taskinstance.py:1359} INFO - 
--------------------------------------------------------------------------------
[2024-09-17 12:36:21,728] {taskinstance.py:1378} INFO - Executing <Task(PythonOperator): run_hespress_task> on 2024-09-17 11:36:18.915604+00:00
[2024-09-17 12:36:21,747] {standard_task_runner.py:52} INFO - Started process 2017 to run task
[2024-09-17 12:36:21,757] {standard_task_runner.py:79} INFO - Running: ['***', 'tasks', 'run', 'scrapy_spiders_dag', 'run_hespress_task', 'scheduled__2024-09-17T11:36:18.915604+00:00', '--job-id', '61', '--raw', '--subdir', 'DAGS_FOLDER/stream.py', '--cfg-path', '/tmp/tmpb0d8hypg', '--error-file', '/tmp/tmp3d3gh8pa']
[2024-09-17 12:36:21,759] {standard_task_runner.py:80} INFO - Job 61: Subtask run_hespress_task
[2024-09-17 12:36:21,942] {task_command.py:370} INFO - Running <TaskInstance: scrapy_spiders_dag.run_hespress_task scheduled__2024-09-17T11:36:18.915604+00:00 [running]> on host 8fbdbf823548
[2024-09-17 12:36:22,156] {taskinstance.py:1572} INFO - Exporting the following env vars:
AIRFLOW_CTX_DAG_OWNER=***
AIRFLOW_CTX_DAG_ID=scrapy_spiders_dag
AIRFLOW_CTX_TASK_ID=run_hespress_task
AIRFLOW_CTX_EXECUTION_DATE=2024-09-17T11:36:18.915604+00:00
AIRFLOW_CTX_TRY_NUMBER=1
AIRFLOW_CTX_DAG_RUN_ID=scheduled__2024-09-17T11:36:18.915604+00:00
[2024-09-17 12:36:22,163] {conn.py:381} INFO - <BrokerConnection node_id=bootstrap-0 host=broker:29092 <connecting> [IPv4 ('172.18.0.8', 29092)]>: connecting to broker:29092 [('172.18.0.8', 29092) IPv4]
[2024-09-17 12:36:22,164] {conn.py:1205} INFO - Probing node bootstrap-0 broker version
[2024-09-17 12:36:22,168] {conn.py:410} INFO - <BrokerConnection node_id=bootstrap-0 host=broker:29092 <connecting> [IPv4 ('172.18.0.8', 29092)]>: Connection complete.
[2024-09-17 12:36:22,280] {conn.py:1267} INFO - Broker version identified as 2.5.0
[2024-09-17 12:36:22,280] {conn.py:1269} INFO - Set configuration api_version=(2, 5, 0) to skip auto check_version requests on startup
[2024-09-17 12:36:22,320] {logging_mixin.py:115} WARNING - --- Logging error ---
[2024-09-17 12:36:22,326] {logging_mixin.py:115} WARNING - Traceback (most recent call last):
[2024-09-17 12:36:22,326] {logging_mixin.py:115} WARNING -   File "/home/***/.local/lib/python3.7/site-packages/urllib3/connection.py", line 175, in _new_conn
    (self._dns_host, self.port), self.timeout, **extra_kw
[2024-09-17 12:36:22,326] {logging_mixin.py:115} WARNING -   File "/home/***/.local/lib/python3.7/site-packages/urllib3/util/connection.py", line 72, in create_connection
    for res in socket.getaddrinfo(host, port, family, socket.SOCK_STREAM):
[2024-09-17 12:36:22,326] {logging_mixin.py:115} WARNING -   File "/usr/local/lib/python3.7/socket.py", line 752, in getaddrinfo
    for res in _socket.getaddrinfo(host, port, family, type, proto, flags):
[2024-09-17 12:36:22,327] {logging_mixin.py:115} WARNING - socket.gaierror: [Errno -3] Temporary failure in name resolution
[2024-09-17 12:36:22,327] {logging_mixin.py:115} WARNING - 
During handling of the above exception, another exception occurred:
[2024-09-17 12:36:22,327] {logging_mixin.py:115} WARNING - Traceback (most recent call last):
[2024-09-17 12:36:22,327] {logging_mixin.py:115} WARNING -   File "/home/***/.local/lib/python3.7/site-packages/urllib3/connectionpool.py", line 710, in urlopen
    chunked=chunked,
[2024-09-17 12:36:22,327] {logging_mixin.py:115} WARNING -   File "/home/***/.local/lib/python3.7/site-packages/urllib3/connectionpool.py", line 386, in _make_request
    self._validate_conn(conn)
[2024-09-17 12:36:22,327] {logging_mixin.py:115} WARNING -   File "/home/***/.local/lib/python3.7/site-packages/urllib3/connectionpool.py", line 1040, in _validate_conn
    conn.connect()
[2024-09-17 12:36:22,327] {logging_mixin.py:115} WARNING -   File "/home/***/.local/lib/python3.7/site-packages/urllib3/connection.py", line 358, in connect
    self.sock = conn = self._new_conn()
[2024-09-17 12:36:22,327] {logging_mixin.py:115} WARNING -   File "/home/***/.local/lib/python3.7/site-packages/urllib3/connection.py", line 187, in _new_conn
    self, "Failed to establish a new connection: %s" % e
[2024-09-17 12:36:22,327] {logging_mixin.py:115} WARNING - urllib3.exceptions.NewConnectionError: <urllib3.connection.HTTPSConnection object at 0x7747156448d0>: Failed to establish a new connection: [Errno -3] Temporary failure in name resolution
[2024-09-17 12:36:22,327] {logging_mixin.py:115} WARNING - 
During handling of the above exception, another exception occurred:
[2024-09-17 12:36:22,327] {logging_mixin.py:115} WARNING - Traceback (most recent call last):
[2024-09-17 12:36:22,327] {logging_mixin.py:115} WARNING -   File "/home/***/.local/lib/python3.7/site-packages/requests/adapters.py", line 450, in send
    timeout=timeout
[2024-09-17 12:36:22,327] {logging_mixin.py:115} WARNING -   File "/home/***/.local/lib/python3.7/site-packages/urllib3/connectionpool.py", line 786, in urlopen
    method, url, error=e, _pool=self, _stacktrace=sys.exc_info()[2]
[2024-09-17 12:36:22,327] {logging_mixin.py:115} WARNING -   File "/home/***/.local/lib/python3.7/site-packages/urllib3/util/retry.py", line 592, in increment
    raise MaxRetryError(_pool, url, error or ResponseError(cause))
[2024-09-17 12:36:22,327] {logging_mixin.py:115} WARNING - urllib3.exceptions.MaxRetryError: HTTPSConnectionPool(host='www.hespress.com', port=443): Max retries exceeded with url: / (Caused by NewConnectionError('<urllib3.connection.HTTPSConnection object at 0x7747156448d0>: Failed to establish a new connection: [Errno -3] Temporary failure in name resolution'))
[2024-09-17 12:36:22,327] {logging_mixin.py:115} WARNING - 
During handling of the above exception, another exception occurred:
[2024-09-17 12:36:22,328] {logging_mixin.py:115} WARNING - Traceback (most recent call last):
[2024-09-17 12:36:22,328] {logging_mixin.py:115} WARNING -   File "/opt/***/dags/stream.py", line 19, in scrape_hespress
    response = requests.get(start_url)
[2024-09-17 12:36:22,328] {logging_mixin.py:115} WARNING -   File "/home/***/.local/lib/python3.7/site-packages/requests/api.py", line 75, in get
    return request('get', url, params=params, **kwargs)
[2024-09-17 12:36:22,328] {logging_mixin.py:115} WARNING -   File "/home/***/.local/lib/python3.7/site-packages/requests/api.py", line 61, in request
    return session.request(method=method, url=url, **kwargs)
[2024-09-17 12:36:22,328] {logging_mixin.py:115} WARNING -   File "/home/***/.local/lib/python3.7/site-packages/requests/sessions.py", line 529, in request
    resp = self.send(prep, **send_kwargs)
[2024-09-17 12:36:22,328] {logging_mixin.py:115} WARNING -   File "/home/***/.local/lib/python3.7/site-packages/requests/sessions.py", line 645, in send
    r = adapter.send(request, **kwargs)
[2024-09-17 12:36:22,328] {logging_mixin.py:115} WARNING -   File "/home/***/.local/lib/python3.7/site-packages/requests/adapters.py", line 519, in send
    raise ConnectionError(e, request=request)
[2024-09-17 12:36:22,328] {logging_mixin.py:115} WARNING - requests.exceptions.ConnectionError: HTTPSConnectionPool(host='www.hespress.com', port=443): Max retries exceeded with url: / (Caused by NewConnectionError('<urllib3.connection.HTTPSConnection object at 0x7747156448d0>: Failed to establish a new connection: [Errno -3] Temporary failure in name resolution'))
[2024-09-17 12:36:22,328] {logging_mixin.py:115} WARNING - 
During handling of the above exception, another exception occurred:
[2024-09-17 12:36:22,328] {logging_mixin.py:115} WARNING - Traceback (most recent call last):
[2024-09-17 12:36:22,328] {logging_mixin.py:115} WARNING -   File "/usr/local/lib/python3.7/logging/__init__.py", line 1025, in emit
    msg = self.format(record)
[2024-09-17 12:36:22,331] {logging_mixin.py:115} WARNING -   File "/usr/local/lib/python3.7/logging/__init__.py", line 869, in format
    return fmt.format(record)
[2024-09-17 12:36:22,331] {logging_mixin.py:115} WARNING -   File "/usr/local/lib/python3.7/logging/__init__.py", line 608, in format
    record.message = record.getMessage()
[2024-09-17 12:36:22,331] {logging_mixin.py:115} WARNING -   File "/usr/local/lib/python3.7/logging/__init__.py", line 369, in getMessage
    msg = msg % self.args
[2024-09-17 12:36:22,331] {logging_mixin.py:115} WARNING - TypeError: not all arguments converted during string formatting
[2024-09-17 12:36:22,331] {logging_mixin.py:115} WARNING - Call stack:
[2024-09-17 12:36:22,352] {logging_mixin.py:115} WARNING -   File "/home/***/.local/bin/***", line 8, in <module>
    sys.exit(main())
[2024-09-17 12:36:22,352] {logging_mixin.py:115} WARNING -   File "/home/***/.local/lib/python3.7/site-packages/***/__main__.py", line 38, in main
    args.func(args)
[2024-09-17 12:36:22,352] {logging_mixin.py:115} WARNING -   File "/home/***/.local/lib/python3.7/site-packages/***/cli/cli_parser.py", line 51, in command
    return func(*args, **kwargs)
[2024-09-17 12:36:22,352] {logging_mixin.py:115} WARNING -   File "/home/***/.local/lib/python3.7/site-packages/***/utils/cli.py", line 99, in wrapper
    return f(*args, **kwargs)
[2024-09-17 12:36:22,352] {logging_mixin.py:115} WARNING -   File "/home/***/.local/lib/python3.7/site-packages/***/cli/commands/celery_command.py", line 194, in worker
    _run_worker(options=options, skip_serve_logs=skip_serve_logs)
[2024-09-17 12:36:22,352] {logging_mixin.py:115} WARNING -   File "/home/***/.local/lib/python3.7/site-packages/***/cli/commands/celery_command.py", line 94, in _run_worker
    celery_app.worker_main(options)
[2024-09-17 12:36:22,353] {logging_mixin.py:115} WARNING -   File "/home/***/.local/lib/python3.7/site-packages/celery/app/base.py", line 391, in worker_main
    self.start(argv=argv)
[2024-09-17 12:36:22,353] {logging_mixin.py:115} WARNING -   File "/home/***/.local/lib/python3.7/site-packages/celery/app/base.py", line 371, in start
    celery.main(args=argv, standalone_mode=False)
[2024-09-17 12:36:22,353] {logging_mixin.py:115} WARNING -   File "/home/***/.local/lib/python3.7/site-packages/click/core.py", line 1055, in main
    rv = self.invoke(ctx)
[2024-09-17 12:36:22,354] {logging_mixin.py:115} WARNING -   File "/home/***/.local/lib/python3.7/site-packages/click/core.py", line 1657, in invoke
    return _process_result(sub_ctx.command.invoke(sub_ctx))
[2024-09-17 12:36:22,354] {logging_mixin.py:115} WARNING -   File "/home/***/.local/lib/python3.7/site-packages/click/core.py", line 1404, in invoke
    return ctx.invoke(self.callback, **ctx.params)
[2024-09-17 12:36:22,354] {logging_mixin.py:115} WARNING -   File "/home/***/.local/lib/python3.7/site-packages/click/core.py", line 760, in invoke
    return __callback(*args, **kwargs)
[2024-09-17 12:36:22,354] {logging_mixin.py:115} WARNING -   File "/home/***/.local/lib/python3.7/site-packages/click/decorators.py", line 26, in new_func
    return f(get_current_context(), *args, **kwargs)
[2024-09-17 12:36:22,354] {logging_mixin.py:115} WARNING -   File "/home/***/.local/lib/python3.7/site-packages/celery/bin/base.py", line 134, in caller
    return f(ctx, *args, **kwargs)
[2024-09-17 12:36:22,354] {logging_mixin.py:115} WARNING -   File "/home/***/.local/lib/python3.7/site-packages/celery/bin/worker.py", line 351, in worker
    worker.start()
[2024-09-17 12:36:22,354] {logging_mixin.py:115} WARNING -   File "/home/***/.local/lib/python3.7/site-packages/celery/worker/worker.py", line 203, in start
    self.blueprint.start(self)
[2024-09-17 12:36:22,354] {logging_mixin.py:115} WARNING -   File "/home/***/.local/lib/python3.7/site-packages/celery/bootsteps.py", line 116, in start
    step.start(parent)
[2024-09-17 12:36:22,354] {logging_mixin.py:115} WARNING -   File "/home/***/.local/lib/python3.7/site-packages/celery/bootsteps.py", line 365, in start
    return self.obj.start()
[2024-09-17 12:36:22,354] {logging_mixin.py:115} WARNING -   File "/home/***/.local/lib/python3.7/site-packages/celery/concurrency/base.py", line 129, in start
    self.on_start()
[2024-09-17 12:36:22,354] {logging_mixin.py:115} WARNING -   File "/home/***/.local/lib/python3.7/site-packages/celery/concurrency/prefork.py", line 115, in on_start
    **self.options)
[2024-09-17 12:36:22,354] {logging_mixin.py:115} WARNING -   File "/home/***/.local/lib/python3.7/site-packages/celery/concurrency/asynpool.py", line 463, in __init__
    super().__init__(processes, *args, **kwargs)
[2024-09-17 12:36:22,354] {logging_mixin.py:115} WARNING -   File "/home/***/.local/lib/python3.7/site-packages/billiard/pool.py", line 1046, in __init__
    self._create_worker_process(i)
[2024-09-17 12:36:22,354] {logging_mixin.py:115} WARNING -   File "/home/***/.local/lib/python3.7/site-packages/celery/concurrency/asynpool.py", line 480, in _create_worker_process
    return super()._create_worker_process(i)
[2024-09-17 12:36:22,355] {logging_mixin.py:115} WARNING -   File "/home/***/.local/lib/python3.7/site-packages/billiard/pool.py", line 1158, in _create_worker_process
    w.start()
[2024-09-17 12:36:22,355] {logging_mixin.py:115} WARNING -   File "/home/***/.local/lib/python3.7/site-packages/billiard/process.py", line 124, in start
    self._popen = self._Popen(self)
[2024-09-17 12:36:22,355] {logging_mixin.py:115} WARNING -   File "/home/***/.local/lib/python3.7/site-packages/billiard/context.py", line 333, in _Popen
    return Popen(process_obj)
[2024-09-17 12:36:22,355] {logging_mixin.py:115} WARNING -   File "/home/***/.local/lib/python3.7/site-packages/billiard/popen_fork.py", line 24, in __init__
    self._launch(process_obj)
[2024-09-17 12:36:22,355] {logging_mixin.py:115} WARNING -   File "/home/***/.local/lib/python3.7/site-packages/billiard/popen_fork.py", line 79, in _launch
    code = process_obj._bootstrap()
[2024-09-17 12:36:22,355] {logging_mixin.py:115} WARNING -   File "/home/***/.local/lib/python3.7/site-packages/billiard/process.py", line 327, in _bootstrap
    self.run()
[2024-09-17 12:36:22,355] {logging_mixin.py:115} WARNING -   File "/home/***/.local/lib/python3.7/site-packages/billiard/process.py", line 114, in run
    self._target(*self._args, **self._kwargs)
[2024-09-17 12:36:22,355] {logging_mixin.py:115} WARNING -   File "/home/***/.local/lib/python3.7/site-packages/billiard/pool.py", line 292, in __call__
    sys.exit(self.workloop(pid=pid))
[2024-09-17 12:36:22,355] {logging_mixin.py:115} WARNING -   File "/home/***/.local/lib/python3.7/site-packages/billiard/pool.py", line 362, in workloop
    result = (True, prepare_result(fun(*args, **kwargs)))
[2024-09-17 12:36:22,355] {logging_mixin.py:115} WARNING -   File "/home/***/.local/lib/python3.7/site-packages/celery/app/trace.py", line 650, in fast_trace_task
    uuid, args, kwargs, request,
[2024-09-17 12:36:22,355] {logging_mixin.py:115} WARNING -   File "/home/***/.local/lib/python3.7/site-packages/celery/app/trace.py", line 451, in trace_task
    R = retval = fun(*args, **kwargs)
[2024-09-17 12:36:22,355] {logging_mixin.py:115} WARNING -   File "/home/***/.local/lib/python3.7/site-packages/celery/app/trace.py", line 734, in __protected_call__
    return self.run(*args, **kwargs)
[2024-09-17 12:36:22,355] {logging_mixin.py:115} WARNING -   File "/home/***/.local/lib/python3.7/site-packages/***/executors/celery_executor.py", line 93, in execute_command
    _execute_in_fork(command_to_exec, celery_task_id)
[2024-09-17 12:36:22,355] {logging_mixin.py:115} WARNING -   File "/home/***/.local/lib/python3.7/site-packages/***/executors/celery_executor.py", line 128, in _execute_in_fork
    args.func(args)
[2024-09-17 12:36:22,355] {logging_mixin.py:115} WARNING -   File "/home/***/.local/lib/python3.7/site-packages/***/cli/cli_parser.py", line 51, in command
    return func(*args, **kwargs)
[2024-09-17 12:36:22,355] {logging_mixin.py:115} WARNING -   File "/home/***/.local/lib/python3.7/site-packages/***/utils/cli.py", line 99, in wrapper
    return f(*args, **kwargs)
[2024-09-17 12:36:22,355] {logging_mixin.py:115} WARNING -   File "/home/***/.local/lib/python3.7/site-packages/***/cli/commands/task_command.py", line 376, in task_run
    _run_task_by_selected_method(args, dag, ti)
[2024-09-17 12:36:22,355] {logging_mixin.py:115} WARNING -   File "/home/***/.local/lib/python3.7/site-packages/***/cli/commands/task_command.py", line 182, in _run_task_by_selected_method
    _run_task_by_local_task_job(args, ti)
[2024-09-17 12:36:22,356] {logging_mixin.py:115} WARNING -   File "/home/***/.local/lib/python3.7/site-packages/***/cli/commands/task_command.py", line 240, in _run_task_by_local_task_job
    run_job.run()
[2024-09-17 12:36:22,356] {logging_mixin.py:115} WARNING -   File "/home/***/.local/lib/python3.7/site-packages/***/jobs/base_job.py", line 244, in run
    self._execute()
[2024-09-17 12:36:22,356] {logging_mixin.py:115} WARNING -   File "/home/***/.local/lib/python3.7/site-packages/***/jobs/local_task_job.py", line 105, in _execute
    self.task_runner.start()
[2024-09-17 12:36:22,356] {logging_mixin.py:115} WARNING -   File "/home/***/.local/lib/python3.7/site-packages/***/task/task_runner/standard_task_runner.py", line 41, in start
    self.process = self._start_by_fork()
[2024-09-17 12:36:22,356] {logging_mixin.py:115} WARNING -   File "/home/***/.local/lib/python3.7/site-packages/***/task/task_runner/standard_task_runner.py", line 88, in _start_by_fork
    args.func(args, dag=self.dag)
[2024-09-17 12:36:22,356] {logging_mixin.py:115} WARNING -   File "/home/***/.local/lib/python3.7/site-packages/***/cli/cli_parser.py", line 51, in command
    return func(*args, **kwargs)
[2024-09-17 12:36:22,356] {logging_mixin.py:115} WARNING -   File "/home/***/.local/lib/python3.7/site-packages/***/utils/cli.py", line 99, in wrapper
    return f(*args, **kwargs)
[2024-09-17 12:36:22,356] {logging_mixin.py:115} WARNING -   File "/home/***/.local/lib/python3.7/site-packages/***/cli/commands/task_command.py", line 376, in task_run
    _run_task_by_selected_method(args, dag, ti)
[2024-09-17 12:36:22,356] {logging_mixin.py:115} WARNING -   File "/home/***/.local/lib/python3.7/site-packages/***/cli/commands/task_command.py", line 184, in _run_task_by_selected_method
    _run_raw_task(args, ti)
[2024-09-17 12:36:22,357] {logging_mixin.py:115} WARNING -   File "/home/***/.local/lib/python3.7/site-packages/***/cli/commands/task_command.py", line 261, in _run_raw_task
    error_file=args.error_file,
[2024-09-17 12:36:22,357] {logging_mixin.py:115} WARNING -   File "/home/***/.local/lib/python3.7/site-packages/***/utils/session.py", line 71, in wrapper
    return func(*args, session=session, **kwargs)
[2024-09-17 12:36:22,357] {logging_mixin.py:115} WARNING -   File "/home/***/.local/lib/python3.7/site-packages/***/models/taskinstance.py", line 1452, in _run_raw_task
    self._execute_task_with_callbacks(context, test_mode)
[2024-09-17 12:36:22,357] {logging_mixin.py:115} WARNING -   File "/home/***/.local/lib/python3.7/site-packages/***/models/taskinstance.py", line 1599, in _execute_task_with_callbacks
    result = self._execute_task(context, task_orig)
[2024-09-17 12:36:22,357] {logging_mixin.py:115} WARNING -   File "/home/***/.local/lib/python3.7/site-packages/***/models/taskinstance.py", line 1660, in _execute_task
    result = execute_callable(context=context)
[2024-09-17 12:36:22,357] {logging_mixin.py:115} WARNING -   File "/home/***/.local/lib/python3.7/site-packages/***/operators/python.py", line 171, in execute
    return_value = self.execute_callable()
[2024-09-17 12:36:22,357] {logging_mixin.py:115} WARNING -   File "/home/***/.local/lib/python3.7/site-packages/***/operators/python.py", line 189, in execute_callable
    return self.python_callable(*self.op_args, **self.op_kwargs)
[2024-09-17 12:36:22,357] {logging_mixin.py:115} WARNING -   File "/opt/***/dags/stream.py", line 36, in scrape_hespress
    logging.error("Error occurred fetching data from hespress", e)
[2024-09-17 12:36:22,357] {logging_mixin.py:115} WARNING -   File "/usr/local/lib/python3.7/logging/__init__.py", line 1959, in error
    root.error(msg, *args, **kwargs)
[2024-09-17 12:36:22,357] {logging_mixin.py:115} WARNING -   File "/usr/local/lib/python3.7/logging/__init__.py", line 1407, in error
    self._log(ERROR, msg, args, **kwargs)
[2024-09-17 12:36:22,357] {logging_mixin.py:115} WARNING -   File "/usr/local/lib/python3.7/logging/__init__.py", line 1514, in _log
    self.handle(record)
[2024-09-17 12:36:22,358] {logging_mixin.py:115} WARNING -   File "/usr/local/lib/python3.7/logging/__init__.py", line 1524, in handle
    self.callHandlers(record)
[2024-09-17 12:36:22,358] {logging_mixin.py:115} WARNING -   File "/usr/local/lib/python3.7/logging/__init__.py", line 1586, in callHandlers
    hdlr.handle(record)
[2024-09-17 12:36:22,358] {logging_mixin.py:115} WARNING -   File "/usr/local/lib/python3.7/logging/__init__.py", line 894, in handle
    self.emit(record)
[2024-09-17 12:36:22,358] {logging_mixin.py:115} WARNING -   File "/home/***/.local/lib/python3.7/site-packages/***/utils/log/file_task_handler.py", line 67, in emit
    self.handler.emit(record)
[2024-09-17 12:36:22,358] {logging_mixin.py:115} WARNING - Message: 'Error occurred fetching data from hespress'
Arguments: (ConnectionError(MaxRetryError("HTTPSConnectionPool(host='www.hespress.com', port=443): Max retries exceeded with url: / (Caused by NewConnectionError('<urllib3.connection.HTTPSConnection object at 0x7747156448d0>: Failed to establish a new connection: [Errno -3] Temporary failure in name resolution'))")),)
[2024-09-17 12:36:22,363] {conn.py:919} INFO - <BrokerConnection node_id=bootstrap-0 host=broker:29092 <connected> [IPv4 ('172.18.0.8', 29092)]>: Closing connection. 
[2024-09-17 12:36:22,424] {local_task_job.py:156} INFO - Task exited with return code 1
[2024-09-17 12:36:22,471] {taskinstance.py:1401} INFO - Marking task as FAILED. dag_id=scrapy_spiders_dag, task_id=run_hespress_task, execution_date=20240917T113618, start_date=20240917T123621, end_date=20240917T123622
[2024-09-17 12:36:22,528] {local_task_job.py:273} INFO - 0 downstream tasks scheduled from follow-on schedule check
